Workbook

Sheet Bills
A1: Bill Name | B1: Amount | C1: Due Day | D1: Next Due Date | E1: Frequency | F1: Include? | G1: Effective Due Date | H1: Counts This Cycle (True/False) | I1: Adjusted Due Date | J1: Category | K1: Autopay? | L1: Last Paid | M1: Annual Cost | N1: Notes | O1: Due Rank
A2: Gym Membership | B2: 27 | C2: 2 | D2: =IF( DATE( YEAR(TODAY()), MONTH(TODAY()), MIN(C2, DAY(EOMONTH(TODAY(), 0))) ) >= TODAY(), DATE( YEAR(TODAY()), MONTH(TODAY()), MIN(C2, DAY(EOMONTH(TODAY(), 0))) ), EDATE( DATE( YEAR(TODAY()), MONTH(TODAY()), MIN(C2, DAY(EOMONTH(TODAY(), 0))) ), 1 ) ) -> 46144 | E2: Monthly | F2: TRUE | G2: =IF($D2="","",IFERROR($D2-Dashboard!$B$14,"")) -> 46143 | H2: =AND($F2=TRUE,$B2>0,$D2>=TODAY(),$D2<Dashboard!$B$4) -> TRUE | I2: =IF(D2="","",D2-Dashboard!$B$14) -> 46143 | J2: Discretionary | K2: TRUE | M2: =IF(E2="Monthly",B2*12,IF(E2="Quarterly",B2*4,IF(E2="Annual",B2,B2*12))) -> 324 | O2: {=IF(AND(F2=TRUE,D2<>""),SUMPRODUCT((D$2:D$13<D2)*(F$2:F$13=TRUE)*(D$2:D$13<>""))+SUMPRODUCT((D$2:D$13=D2)*(F$2:F$13=TRUE)*(D$2:D$13<>"")*($A$2:$A$13<A2))+1,"")} -> 1
A3: Phone Bill (Verizon) | B3: 65 | C3: 2 | D3: =IF(OR(C3="",F3=FALSE),"",IF(DATE(YEAR(TODAY()),MONTH(TODAY()),C3)>=TODAY(),DATE(YEAR(TODAY()),MONTH(TODAY()),C3),EDATE(DATE(YEAR(TODAY()),MONTH(TODAY()),C3),1))) -> 46144 | E3: Monthly | F3: TRUE | G3: =IF($D3="","",IFERROR($D3-Dashboard!$B$14,"")) -> 46143 | H3: =AND($F3=TRUE,$B3>0,$D3>=TODAY(),$D3<Dashboard!$B$4) -> TRUE | I3: =IF(D3="","",D3-Dashboard!$B$14) -> 46143 | J3: Essential | K3: TRUE | M3: =IF(E3="Monthly",B3*12,IF(E3="Quarterly",B3*4,IF(E3="Annual",B3,B3*12))) -> 780 | O3: {=IF(AND(F3=TRUE,D3<>""),SUMPRODUCT((D$2:D$13<D3)*(F$2:F$13=TRUE)*(D$2:D$13<>""))+SUMPRODUCT((D$2:D$13=D3)*(F$2:F$13=TRUE)*(D$2:D$13<>"")*($A$2:$A$13<A3))+1,"")} -> 2
A4: Claude Subscription | B4: 21 | C4: 3 | D4: =IF(OR(C4="",F4=FALSE),"",IF(DATE(YEAR(TODAY()),MONTH(TODAY()),C4)>=TODAY(),DATE(YEAR(TODAY()),MONTH(TODAY()),C4),EDATE(DATE(YEAR(TODAY()),MONTH(TODAY()),C4),1))) -> 46145 | E4: Monthly | F4: TRUE | G4: =IF($D4="","",IFERROR($D4-Dashboard!$B$14,"")) -> 46144 | H4: =AND($F4=TRUE,$B4>0,$D4>=TODAY(),$D4<Dashboard!$B$4) -> TRUE | I4: =IF(D4="","",D4-Dashboard!$B$14) -> 46144 | J4: Discretionary | K4: TRUE | M4: =IF(E4="Monthly",B4*12,IF(E4="Quarterly",B4*4,IF(E4="Annual",B4,B4*12))) -> 252 | N4: Subscription | O4: {=IF(AND(F4=TRUE,D4<>""),SUMPRODUCT((D$2:D$13<D4)*(F$2:F$13=TRUE)*(D$2:D$13<>""))+SUMPRODUCT((D$2:D$13=D4)*(F$2:F$13=TRUE)*(D$2:D$13<>"")*($A$2:$A$13<A4))+1,"")} -> 3
A5: Rent | B5: 1000 | C5: 4 | D5: =IF(OR(C5="",F5=FALSE),"",IF(DATE(YEAR(TODAY()),MONTH(TODAY()),C5)>=TODAY(),DATE(YEAR(TODAY()),MONTH(TODAY()),C5),EDATE(DATE(YEAR(TODAY()),MONTH(TODAY()),C5),1))) -> 46146 | E5: Monthly | F5: TRUE | G5: =IF($D5="","",IFERROR($D5-Dashboard!$B$14,"")) -> 46145 | H5: =AND($F5=TRUE,$B5>0,$D5>=TODAY(),$D5<Dashboard!$B$4) -> TRUE | I5: =IF(D5="","",D5-Dashboard!$B$14) -> 46145 | J5: Essential | K5: TRUE | M5: =IF(E5="Monthly",B5*12,IF(E5="Quarterly",B5*4,IF(E5="Annual",B5,B5*12))) -> 12000 | N5: Largest fixed obligation | O5: {=IF(AND(F5=TRUE,D5<>""),SUMPRODUCT((D$2:D$13<D5)*(F$2:F$13=TRUE)*(D$2:D$13<>""))+SUMPRODUCT((D$2:D$13=D5)*(F$2:F$13=TRUE)*(D$2:D$13<>"")*($A$2:$A$13<A5))+1,"")} -> 4
A6: Car Loan | B6: 337 | C6: 4 | D6: =IF(OR(C6="",F6=FALSE),"",IF(DATE(YEAR(TODAY()),MONTH(TODAY()),C6)>=TODAY(),DATE(YEAR(TODAY()),MONTH(TODAY()),C6),EDATE(DATE(YEAR(TODAY()),MONTH(TODAY()),C6),1))) | E6: Monthly | F6: FALSE | G6: =IF($D6="","",IFERROR($D6-Dashboard!$B$14,"")) | H6: =AND($F6=TRUE,$B6>0,$D6>=TODAY(),$D6<Dashboard!$B$4) -> FALSE | I6: =IF(D6="","",D6-Dashboard!$B$14) | J6: Debt | K6: TRUE | M6: =IF(E6="Monthly",B6*12,IF(E6="Quarterly",B6*4,IF(E6="Annual",B6,B6*12))) -> 4044 | N6: Inactive — lien eliminated Mar 2026 | O6: {=IF(AND(F6=TRUE,D6<>""),SUMPRODUCT((D$2:D$13<D6)*(F$2:F$13=TRUE)*(D$2:D$13<>""))+SUMPRODUCT((D$2:D$13=D6)*(F$2:F$13=TRUE)*(D$2:D$13<>"")*($A$2:$A$13<A6))+1,"")}
A7: Car Insurance | B7: 141.95 | C7: 8 | D7: =IF(OR(C7="",F7=FALSE),"",IF(DATE(YEAR(TODAY()),MONTH(TODAY()),C7)>=TODAY(),DATE(YEAR(TODAY()),MONTH(TODAY()),C7),EDATE(DATE(YEAR(TODAY()),MONTH(TODAY()),C7),1))) -> 46150 | E7: Monthly | F7: TRUE | G7: =IF($D7="","",IFERROR($D7-Dashboard!$B$14,"")) -> 46149 | H7: =AND($F7=TRUE,$B7>0,$D7>=TODAY(),$D7<Dashboard!$B$4) -> FALSE | I7: =IF(D7="","",D7-Dashboard!$B$14) -> 46149 | J7: Essential | K7: TRUE | M7: =IF(E7="Monthly",B7*12,IF(E7="Quarterly",B7*4,IF(E7="Annual",B7,B7*12))) -> 1703.4 | O7: {=IF(AND(F7=TRUE,D7<>""),SUMPRODUCT((D$2:D$13<D7)*(F$2:F$13=TRUE)*(D$2:D$13<>""))+SUMPRODUCT((D$2:D$13=D7)*(F$2:F$13=TRUE)*(D$2:D$13<>"")*($A$2:$A$13<A7))+1,"")} -> 5
A8: YouTube Premium | B8: 14 | C8: 15 | D8: =IF(OR(C8="",F8=FALSE),"",IF(DATE(YEAR(TODAY()),MONTH(TODAY()),C8)>=TODAY(),DATE(YEAR(TODAY()),MONTH(TODAY()),C8),EDATE(DATE(YEAR(TODAY()),MONTH(TODAY()),C8),1))) -> 46157 | E8: Monthly | F8: TRUE | G8: =IF($D8="","",IFERROR($D8-Dashboard!$B$14,"")) -> 46156 | H8: =AND($F8=TRUE,$B8>0,$D8>=TODAY(),$D8<Dashboard!$B$4) -> FALSE | I8: =IF(D8="","",D8-Dashboard!$B$14) -> 46156 | J8: Discretionary | K8: TRUE | M8: =IF(E8="Monthly",B8*12,IF(E8="Quarterly",B8*4,IF(E8="Annual",B8,B8*12))) -> 168 | N8: Subscription | O8: {=IF(AND(F8=TRUE,D8<>""),SUMPRODUCT((D$2:D$13<D8)*(F$2:F$13=TRUE)*(D$2:D$13<>""))+SUMPRODUCT((D$2:D$13=D8)*(F$2:F$13=TRUE)*(D$2:D$13<>"")*($A$2:$A$13<A8))+1,"")} -> 6
A9: National Grid (Electric) | B9: 175 | C9: 16 | D9: =IF(OR(C9="",F9=FALSE),"",IF(DATE(YEAR(TODAY()),MONTH(TODAY()),C9)>=TODAY(),DATE(YEAR(TODAY()),MONTH(TODAY()),C9),EDATE(DATE(YEAR(TODAY()),MONTH(TODAY()),C9),1))) -> 46158 | E9: Monthly | F9: TRUE | G9: =IF($D9="","",IFERROR($D9-Dashboard!$B$14,"")) -> 46157 | H9: =AND($F9=TRUE,$B9>0,$D9>=TODAY(),$D9<Dashboard!$B$4) -> FALSE | I9: =IF(D9="","",D9-Dashboard!$B$14) -> 46157 | J9: Essential | K9: FALSE | M9: =IF(E9="Monthly",B9*12,IF(E9="Quarterly",B9*4,IF(E9="Annual",B9,B9*12))) -> 2100 | N9: Utility — amount varies | O9: {=IF(AND(F9=TRUE,D9<>""),SUMPRODUCT((D$2:D$13<D9)*(F$2:F$13=TRUE)*(D$2:D$13<>""))+SUMPRODUCT((D$2:D$13=D9)*(F$2:F$13=TRUE)*(D$2:D$13<>"")*($A$2:$A$13<A9))+1,"")} -> 7
A10: National Fuel (Gas Utility) | B10: 70 | C10: 19 | D10: =IF(OR(C10="",F10=FALSE),"",IF(DATE(YEAR(TODAY()),MONTH(TODAY()),C10)>=TODAY(),DATE(YEAR(TODAY()),MONTH(TODAY()),C10),EDATE(DATE(YEAR(TODAY()),MONTH(TODAY()),C10),1))) -> 46161 | E10: Monthly | F10: TRUE | G10: =IF($D10="","",IFERROR($D10-Dashboard!$B$14,"")) -> 46160 | H10: =AND($F10=TRUE,$B10>0,$D10>=TODAY(),$D10<Dashboard!$B$4) -> FALSE | I10: =IF(D10="","",D10-Dashboard!$B$14) -> 46160 | J10: Essential | K10: FALSE | M10: =IF(E10="Monthly",B10*12,IF(E10="Quarterly",B10*4,IF(E10="Annual",B10,B10*12))) -> 840 | N10: Utility — amount varies | O10: {=IF(AND(F10=TRUE,D10<>""),SUMPRODUCT((D$2:D$13<D10)*(F$2:F$13=TRUE)*(D$2:D$13<>""))+SUMPRODUCT((D$2:D$13=D10)*(F$2:F$13=TRUE)*(D$2:D$13<>"")*($A$2:$A$13<A10))+1,"")} -> 8
A11: EZ-Pass / Tolls | B11: 10 | C11: 22 | D11: =IF(OR(C11="",F11=FALSE),"",IF(DATE(YEAR(TODAY()),MONTH(TODAY()),C11)>=TODAY(),DATE(YEAR(TODAY()),MONTH(TODAY()),C11),EDATE(DATE(YEAR(TODAY()),MONTH(TODAY()),C11),1))) -> 46164 | E11: Monthly | F11: TRUE | G11: =IF($D11="","",IFERROR($D11-Dashboard!$B$14,"")) -> 46163 | H11: =AND($F11=TRUE,$B11>0,$D11>=TODAY(),$D11<Dashboard!$B$4) -> FALSE | I11: =IF(D11="","",D11-Dashboard!$B$14) -> 46163 | J11: Essential | K11: TRUE | M11: =IF(E11="Monthly",B11*12,IF(E11="Quarterly",B11*4,IF(E11="Annual",B11,B11*12))) -> 120 | O11: {=IF(AND(F11=TRUE,D11<>""),SUMPRODUCT((D$2:D$13<D11)*(F$2:F$13=TRUE)*(D$2:D$13<>""))+SUMPRODUCT((D$2:D$13=D11)*(F$2:F$13=TRUE)*(D$2:D$13<>"")*($A$2:$A$13<A11))+1,"")} -> 9
A12: Quick Silver Credit Card | B12: 5.98 | E12: Monthly | F12: FALSE | H12: =AND($F12=TRUE,$B12>0,$D12>=TODAY(),$D12<Dashboard!$B$4) -> FALSE | I12: =IF(D12="","",D12-Dashboard!$B$14) | J12: Debt | K12: FALSE | M12: =IF(E12="Monthly",B12*12,IF(E12="Quarterly",B12*4,IF(E12="Annual",B12,B12*12))) -> 71.76 | N12: Excluded — variable CC | O12: {=IF(AND(F12=TRUE,D12<>""),SUMPRODUCT((D$2:D$13<D12)*(F$2:F$13=TRUE)*(D$2:D$13<>""))+SUMPRODUCT((D$2:D$13=D12)*(F$2:F$13=TRUE)*(D$2:D$13<>"")*($A$2:$A$13<A12))+1,"")}
A13: Food + Gas (Variable) | B13: 600 | D13: =IF(OR(C13="",F13=FALSE),"",IF(DATE(YEAR(TODAY()),MONTH(TODAY()),C13)>=TODAY(),DATE(YEAR(TODAY()),MONTH(TODAY()),C13),EDATE(DATE(YEAR(TODAY()),MONTH(TODAY()),C13),1))) | E13: Variable | F13: FALSE | G13: =IF($D13="","",IFERROR($D13-Dashboard!$B$14,"")) | H13: =AND($F13=TRUE,$B13>0,$D13>=TODAY(),$D13<Dashboard!$B$4) -> FALSE | I13: =IF(D13="","",D13-Dashboard!$B$14) | J13: Variable | K13: FALSE | M13: =IF(E13="Monthly",B13*12,IF(E13="Quarterly",B13*4,IF(E13="Annual",B13,B13*12))) -> 7200 | N13: Excluded — tracked in Dashboard variable section | O13: {=IF(AND(F13=TRUE,D13<>""),SUMPRODUCT((D$2:D$13<D13)*(F$2:F$13=TRUE)*(D$2:D$13<>""))+SUMPRODUCT((D$2:D$13=D13)*(F$2:F$13=TRUE)*(D$2:D$13<>"")*($A$2:$A$13<A13))+1,"")}
D14: =IF(OR(C14="",F14=FALSE),"",IF(DATE(YEAR(TODAY()),MONTH(TODAY()),C14)>=TODAY(),DATE(YEAR(TODAY()),MONTH(TODAY()),C14),EDATE(DATE(YEAR(TODAY()),MONTH(TODAY()),C14),1)))
A15: BILL TOTALS & OBLIGATIONS
A16: Total Monthly (Included) | B16: =SUMIFS(B2:B13,F2:F13,TRUE) -> 1523.95 | D16: =IF(OR(C16="",F16=FALSE),"",IF(DATE(YEAR(TODAY()),MONTH(TODAY()),C16)>=TODAY(),DATE(YEAR(TODAY()),MONTH(TODAY()),C16),EDATE(DATE(YEAR(TODAY()),MONTH(TODAY()),C16),1)))
A17: Total Monthly (All Bills) | B17: =SUM(B2:B13) -> 2466.93 | D17: =IF(OR(C17="",F17=FALSE),"",IF(DATE(YEAR(TODAY()),MONTH(TODAY()),C17)>=TODAY(),DATE(YEAR(TODAY()),MONTH(TODAY()),C17),EDATE(DATE(YEAR(TODAY()),MONTH(TODAY()),C17),1)))
A18: Total Annual (Included) | B18: =SUMIFS(M2:M13,F2:F13,TRUE) -> 18287.4 | D18: =IF(OR(C18="",F18=FALSE),"",IF(DATE(YEAR(TODAY()),MONTH(TODAY()),C18)>=TODAY(),DATE(YEAR(TODAY()),MONTH(TODAY()),C18),EDATE(DATE(YEAR(TODAY()),MONTH(TODAY()),C18),1)))
A19: Bills as % of Base Net Income | B19: =IFERROR(B16/Assumptions!B10,0) -> 0.4732764 | D19: =IF(OR(C19="",F19=FALSE),"",IF(DATE(YEAR(TODAY()),MONTH(TODAY()),C19)>=TODAY(),DATE(YEAR(TODAY()),MONTH(TODAY()),C19),EDATE(DATE(YEAR(TODAY()),MONTH(TODAY()),C19),1)))
A20: Active Bill Count | B20: =COUNTIF(F2:F13,TRUE) -> 9 | D20: =IF(OR(C20="",F20=FALSE),"",IF(DATE(YEAR(TODAY()),MONTH(TODAY()),C20)>=TODAY(),DATE(YEAR(TODAY()),MONTH(TODAY()),C20),EDATE(DATE(YEAR(TODAY()),MONTH(TODAY()),C20),1)))
A21: Excluded Bill Count | B21: =COUNTIF(F2:F13,FALSE) -> 3 | D21: =IF(OR(C21="",F21=FALSE),"",IF(DATE(YEAR(TODAY()),MONTH(TODAY()),C21)>=TODAY(),DATE(YEAR(TODAY()),MONTH(TODAY()),C21),EDATE(DATE(YEAR(TODAY()),MONTH(TODAY()),C21),1)))
D22: =IF(OR(C22="",F22=FALSE),"",IF(DATE(YEAR(TODAY()),MONTH(TODAY()),C22)>=TODAY(),DATE(YEAR(TODAY()),MONTH(TODAY()),C22),EDATE(DATE(YEAR(TODAY()),MONTH(TODAY()),C22),1)))
A23: CATEGORY BREAKDOWN
A24: Category | B24: Monthly Total | C24: % of Bills | D24: Annual Total | E24: Bill Count
A25: Essential | B25: =SUMIFS(B2:B13,J2:J13,"Essential",F2:F13,TRUE) -> 1461.95 | C25: =IFERROR(B25/$B$16,0) -> 0.95931625 | D25: =B25*12 -> 17543.4 | E25: =COUNTIFS(J2:J13,"Essential",F2:F13,TRUE) -> 6
A26: Discretionary | B26: =SUMIFS(B2:B13,J2:J13,"Discretionary",F2:F13,TRUE) -> 62 | C26: =IFERROR(B26/$B$16,0) -> 0.040683749 | D26: =B26*12 -> 744 | E26: =COUNTIFS(J2:J13,"Discretionary",F2:F13,TRUE) -> 3
A27: Debt | B27: =SUMIFS(B2:B13,J2:J13,"Debt",F2:F13,TRUE) -> 0 | C27: =IFERROR(B27/$B$16,0) -> 0 | D27: =B27*12 -> 0 | E27: =COUNTIFS(J2:J13,"Debt",F2:F13,TRUE) -> 0
A28: Variable | B28: =SUMIFS(B2:B13,J2:J13,"Variable",F2:F13,TRUE) -> 0 | C28: =IFERROR(B28/$B$16,0) -> 0 | D28: =B28*12 -> 0 | E28: =COUNTIFS(J2:J13,"Variable",F2:F13,TRUE) -> 0
A29: Verification (should = B16) | B29: =SUM(B25:B28) -> 1523.95 | D29: =IF(OR(C29="",F29=FALSE),"",IF(DATE(YEAR(TODAY()),MONTH(TODAY()),C29)>=TODAY(),DATE(YEAR(TODAY()),MONTH(TODAY()),C29),EDATE(DATE(YEAR(TODAY()),MONTH(TODAY()),C29),1)))
D30: =IF(OR(C30="",F30=FALSE),"",IF(DATE(YEAR(TODAY()),MONTH(TODAY()),C30)>=TODAY(),DATE(YEAR(TODAY()),MONTH(TODAY()),C30),EDATE(DATE(YEAR(TODAY()),MONTH(TODAY()),C30),1)))
A31: AUTOPAY AUDIT
A32: Autopay Bills (Count) | B32: =COUNTIFS(K2:K13,TRUE,F2:F13,TRUE) -> 7 | D32: =IF(OR(C32="",F32=FALSE),"",IF(DATE(YEAR(TODAY()),MONTH(TODAY()),C32)>=TODAY(),DATE(YEAR(TODAY()),MONTH(TODAY()),C32),EDATE(DATE(YEAR(TODAY()),MONTH(TODAY()),C32),1)))
A33: Autopay Bills (Monthly $) | B33: =SUMIFS(B2:B13,K2:K13,TRUE,F2:F13,TRUE) -> 1278.95 | D33: =IF(OR(C33="",F33=FALSE),"",IF(DATE(YEAR(TODAY()),MONTH(TODAY()),C33)>=TODAY(),DATE(YEAR(TODAY()),MONTH(TODAY()),C33),EDATE(DATE(YEAR(TODAY()),MONTH(TODAY()),C33),1)))
A34: Manual Bills (Count) | B34: =COUNTIFS(K2:K13,FALSE,F2:F13,TRUE) -> 2 | D34: =IF(OR(C34="",F34=FALSE),"",IF(DATE(YEAR(TODAY()),MONTH(TODAY()),C34)>=TODAY(),DATE(YEAR(TODAY()),MONTH(TODAY()),C34),EDATE(DATE(YEAR(TODAY()),MONTH(TODAY()),C34),1)))
A35: Manual Bills (Monthly $) | B35: =SUMIFS(B2:B13,K2:K13,FALSE,F2:F13,TRUE) -> 245 | D35: =IF(OR(C35="",F35=FALSE),"",IF(DATE(YEAR(TODAY()),MONTH(TODAY()),C35)>=TODAY(),DATE(YEAR(TODAY()),MONTH(TODAY()),C35),EDATE(DATE(YEAR(TODAY()),MONTH(TODAY()),C35),1)))
A36: Manual Bill Due Next | B36: {=IFERROR(MIN(IF((K2:K13=FALSE)*(F2:F13=TRUE)*(D2:D13<>""),D2:D13)),"")} -> 46158 | D36: =IF(OR(C36="",F36=FALSE),"",IF(DATE(YEAR(TODAY()),MONTH(TODAY()),C36)>=TODAY(),DATE(YEAR(TODAY()),MONTH(TODAY()),C36),EDATE(DATE(YEAR(TODAY()),MONTH(TODAY()),C36),1)))
A37: ⚠️ Manual Payment Risk | B37: =IF(B34>0,IF(B36<>"",IF(B36-TODAY()<=3,"🔴 MANUAL BILL DUE WITHIN 3 DAYS",IF(B36-TODAY()<=7,"🟡 Manual bill due within 7 days","🟢 No urgent manual bills")),"🟢 No upcoming manual bills"),"🟢 All bills on autopay") -> 🟢 No urgent manual bills | D37: =IF(OR(C37="",F37=FALSE),"",IF(DATE(YEAR(TODAY()),MONTH(TODAY()),C37)>=TODAY(),DATE(YEAR(TODAY()),MONTH(TODAY()),C37),EDATE(DATE(YEAR(TODAY()),MONTH(TODAY()),C37),1)))
D38: =IF(OR(C38="",F38=FALSE),"",IF(DATE(YEAR(TODAY()),MONTH(TODAY()),C38)>=TODAY(),DATE(YEAR(TODAY()),MONTH(TODAY()),C38),EDATE(DATE(YEAR(TODAY()),MONTH(TODAY()),C38),1)))
A39: UPCOMING BILLS TIMELINE
A40: # | B40: Bill Name | C40: Amount | D40: Due Date | E40: Days Until Due
...

Sheet Dashboard
A1: Personal Finance Dashboard | B1: =TEXT(TODAY(),"MMMM D, YYYY") -> April 23, 2026
A2: Item | B2: Value
A3: TIMING & INPUTS
A4: Next Payday Date | B4: 46149
A5: Last Balance Update | B5: 46135
A6: Available Checking Balance | B6: 2152
A7: Balance Status | B7: =IF(B5=TODAY(),"✅ Balance current","⚠️ Balance NOT updated today") -> ✅ Balance current
A8: Days Since Last Update | B8: =TODAY()-B5 -> 0
A10: OBLIGATIONS & RISKS
A11: Bills Due Before Next Payday | B11: =SUMIFS(Bills!$B$2:$B$13,Bills!$F$2:$F$13,TRUE,Bills!$H$2:$H$13,TRUE) -> 1113
A12: Pending/Holds Reserve | B12: 0
A13: Minimum Cushion | B13: 0
A14: Posting Cushion (Days) | B14: =Assumptions!B2 -> 1
A15: Bills-Only Reserve | B15: =B11 -> 1113
A16: Total Required Hold | B16: =B11+B12+B13+B30+B31+B32+B40 -> 1113
A18: DECISION OUTPUTS
A19: Safe to Spend | B19: =MAX(0, B6 - IF(Assumptions!$B$15=TRUE, B16, B16-B33)) -> 1039
A21: Daily Rate (From Last Update) | B21: =IFERROR(IF(B4<=B5,0,MAX(0,(B19-B24)/(B4-B5))),0) -> 57.071429
A22: Daily Rate (Real-Time) | B22: =IFERROR(IF($B$4<=TODAY(),0,MAX(0,(B19-B24)/($B$4-TODAY()))),0) -> 57.071429
A23: Days of Coverage Remaining | B23: =IFERROR(IF(B21=0,"",B19/B21),"") -> 18.205257
A24: Variable Spend Until Payday | B24: 240
A25: Remaining Discretionary | B25: =MAX(0, B19 - B24) -> 799
A26: Payday Risk | B26: =IF(WEEKDAY($B$4,2)>=6,"WEEKEND PAYDAY RISK","")
A27: Status | B27: {=_xlfn.IFS(B19<=0,"RED",B19<Assumptions!$B$8,"YELLOW",TRUE,"GREEN")} -> GREEN
A29: OPTIONAL BUFFERS
A30: Checking Floor | B30: 0
A31: Irregular Expense Buffer | B31: 0
A32: Timing Buffer | B32: 0
A33: Forward Reserve (Next Month 1st–7th) | B33: =SUMIFS(Bills!$B$2:$B$13,Bills!$F$2:$F$13,TRUE,Bills!$C$2:$C$13,">="&1,Bills!$C$2:$C$13,"<="&7)+(7*(Assumptions!$B$9/Assumptions!$B$4)) -> 1251.1579
A34: ONE-TIME EXPENSES | C34: Due Date
A35: ANRC Event | B35: 159 | C35: 46109
A36: Expense 2
A37: Expense 3
A38: Expense 4
A39: Expense 5
A40: Due Before Payday | B40: {=SUMPRODUCT((B35:B39)*((C35:C39>=TODAY())*(C35:C39<=$B$4)*(B35:B39<>"")))} -> 0
A42: VARIABLE SPEND TRACKING
A43: Monthly Variable Cap | B43: =Assumptions!B9 -> 600
A44: Week 1 Logged Spend | B44: 0
A45: Week 2 Logged Spend | B45: 0
...

Sheet Commissions
A1: Odoo Commission Calculator
A2: Monthly totals — one row per sales month. Enter date, MRR, and NRR; payouts auto-calculate.
A4: ASSUMPTIONS
A5: MRR Target | B5: =Assumptions!B6 -> 700 | D5: NRR Target | E5: =Assumptions!B7 -> 6000
A6: MRR Target Payout | B6: 1424.02 | D6: NRR Target Payout | E6: 611.95
A7: MRR Above-Target Rate | B7: 0.65 | D7: NRR Above-Target Rate | E7: 0.042
A8: Est. Tax Rate | B8: =Assumptions!B3 -> 0.435
A10: Sales Month | B10: MRR Achieved | C10: NRR Achieved | D10: MRR Payout | E10: NRR Payout | F10: Total Gross | G10: Take-Home | H10: Pay-Out Date
A11: 45992 | B11: 890 | C11: 0 | D11: =IF($A11="","",IF(OR($B11="",$B11=0),0,MAX(0,MIN($B11,349.93)-0)*0.3705+MAX(0,MIN($B11,489.93)-349.93)*0.9634+MAX(0,MIN($B11,Assumptions!$B$6-0.07)-489.93)*5.5212+MAX(0,$B11-(Assumptions!$B$6-0.07))*0.65)) -> 1547.5226 | E11: =IF($A11="","",IF(OR($C11="",$C11=0),0,MAX(0,MIN($C11,2999.4)-0)*0.0204+MAX(0,MIN($C11,4199.4)-2999.4)*0.0388+MAX(0,MIN($C11,Assumptions!$B$7-0.6)-4199.4)*0.2801+MAX(0,$C11-(Assumptions!$B$7-0.6))*0.042)) -> 0 | F11: =IF($A11="","",D11+E11) -> 1547.5226 | G11: =IF($A11="","",F11*(1-$B$8)) -> 874.35025 | H11: =IF($A11="","",DATE(YEAR($A11),MONTH($A11)+1,Assumptions!$B$5)) -> 46044
A12: 46023 | B12: 0 | C12: 0 | D12: =IF($A12="","",IF(OR($B12="",$B12=0),0,MAX(0,MIN($B12,349.93)-0)*0.3705+MAX(0,MIN($B12,489.93)-349.93)*0.9634+MAX(0,MIN($B12,Assumptions!$B$6-0.07)-489.93)*5.5212+MAX(0,$B12-(Assumptions!$B$6-0.07))*0.65)) -> 0 | E12: =IF($A12="","",IF(OR($C12="",$C12=0),0,MAX(0,MIN($C12,2999.4)-0)*0.0204+MAX(0,MIN($C12,4199.4)-2999.4)*0.0388+MAX(0,MIN($C12,Assumptions!$B$7-0.6)-4199.4)*0.2801+MAX(0,$C12-(Assumptions!$B$7-0.6))*0.042)) -> 0 | F12: =IF($A12="","",D12+E12) -> 0 | G12: =IF($A12="","",F12*(1-$B$8)) -> 0 | H12: =IF($A12="","",DATE(YEAR($A12),MONTH($A12)+1,Assumptions!$B$5)) -> 46075
A13: 46054 | B13: 245 | C13: 0 | D13: =IF($A13="","",IF(OR($B13="",$B13=0),0,MAX(0,MIN($B13,349.93)-0)*0.3705+MAX(0,MIN($B13,489.93)-349.93)*0.9634+MAX(0,MIN($B13,Assumptions!$B$6-0.07)-489.93)*5.5212+MAX(0,$B13-(Assumptions!$B$6-0.07))*0.65)) -> 90.7725 | E13: =IF($A13="","",IF(OR($C13="",$C13=0),0,MAX(0,MIN($C13,2999.4)-0)*0.0204+MAX(0,MIN($C13,4199.4)-2999.4)*0.0388+MAX(0,MIN($C13,Assumptions!$B$7-0.6)-4199.4)*0.2801+MAX(0,$C13-(Assumptions!$B$7-0.6))*0.042)) -> 0 | F13: =IF($A13="","",D13+E13) -> 90.7725 | G13: =IF($A13="","",F13*(1-$B$8)) -> 51.286462 | H13: =IF($A13="","",DATE(YEAR($A13),MONTH($A13)+1,Assumptions!$B$5)) -> 46103
A14: 46082 | B14: 0 | C14: 0 | D14: =IF($A14="","",IF(OR($B14="",$B14=0),0,MAX(0,MIN($B14,349.93)-0)*0.3705+MAX(0,MIN($B14,489.93)-349.93)*0.9634+MAX(0,MIN($B14,Assumptions!$B$6-0.07)-489.93)*5.5212+MAX(0,$B14-(Assumptions!$B$6-0.07))*0.65)) -> 0 | E14: =IF($A14="","",IF(OR($C14="",$C14=0),0,MAX(0,MIN($C14,2999.4)-0)*0.0204+MAX(0,MIN($C14,4199.4)-2999.4)*0.0388+MAX(0,MIN($C14,Assumptions!$B$7-0.6)-4199.4)*0.2801+MAX(0,$C14-(Assumptions!$B$7-0.6))*0.042)) -> 0 | F14: =IF($A14="","",D14+E14) -> 0 | G14: =IF($A14="","",F14*(1-$B$8)) -> 0 | H14: =IF($A14="","",DATE(YEAR($A14),MONTH($A14)+1,Assumptions!$B$5)) -> 46134
A15: 46113 | B15: 0 | C15: 0 | D15: =IF($A15="","",IF(OR($B15="",$B15=0),0,MAX(0,MIN($B15,349.93)-0)*0.3705+MAX(0,MIN($B15,489.93)-349.93)*0.9634+MAX(0,MIN($B15,Assumptions!$B$6-0.07)-489.93)*5.5212+MAX(0,$B15-(Assumptions!$B$6-0.07))*0.65)) -> 0 | E15: =IF($A15="","",IF(OR($C15="",$C15=0),0,MAX(0,MIN($C15,2999.4)-0)*0.0204+MAX(0,MIN($C15,4199.4)-2999.4)*0.0388+MAX(0,MIN($C15,Assumptions!$B$7-0.6)-4199.4)*0.2801+MAX(0,$C15-(Assumptions!$B$7-0.6))*0.042)) -> 0 | F15: =IF($A15="","",D15+E15) -> 0 | G15: =IF($A15="","",F15*(1-$B$8)) -> 0 | H15: =IF($A15="","",DATE(YEAR($A15),MONTH($A15)+1,Assumptions!$B$5)) -> 46164
D16: =IF($A16="","",IF(OR($B16="",$B16=0),0,MAX(0,MIN($B16,349.93)-0)*0.3705+MAX(0,MIN($B16,489.93)-349.93)*0.9634+MAX(0,MIN($B16,Assumptions!$B$6-0.07)-489.93)*5.5212+MAX(0,$B16-(Assumptions!$B$6-0.07))*0.65)) | E16: =IF($A16="","",IF(OR($C16="",$C16=0),0,MAX(0,MIN($C16,2999.4)-0)*0.0204+MAX(0,MIN($C16,4199.4)-2999.4)*0.0388+MAX(0,MIN($C16,Assumptions!$B$7-0.6)-4199.4)*0.2801+MAX(0,$C16-(Assumptions!$B$7-0.6))*0.042)) | F16: =IF($A16="","",D16+E16) | G16: =IF($A16="","",F16*(1-$B$8)) | H16: =IF($A16="","",DATE(YEAR($A16),MONTH($A16)+1,Assumptions!$B$5))
D17: =IF($A17="","",IF(OR($B17="",$B17=0),0,MAX(0,MIN($B17,349.93)-0)*0.3705+MAX(0,MIN($B17,489.93)-349.93)*0.9634+MAX(0,MIN($B17,Assumptions!$B$6-0.07)-489.93)*5.5212+MAX(0,$B17-(Assumptions!$B$6-0.07))*0.65)) | E17: =IF($A17="","",IF(OR($C17="",$C17=0),0,MAX(0,MIN($C17,2999.4)-0)*0.0204+MAX(0,MIN($C17,4199.4)-2999.4)*0.0388+MAX(0,MIN($C17,Assumptions!$B$7-0.6)-4199.4)*0.2801+MAX(0,$C17-(Assumptions!$B$7-0.6))*0.042)) | F17: =IF($A17="","",D17+E17) | G17: =IF($A17="","",F17*(1-$B$8)) | H17: =IF($A17="","",DATE(YEAR($A17),MONTH($A17)+1,Assumptions!$B$5))
D18: =IF($A18="","",IF(OR($B18="",$B18=0),0,MAX(0,MIN($B18,349.93)-0)*0.3705+MAX(0,MIN($B18,489.93)-349.93)*0.9634+MAX(0,MIN($B18,Assumptions!$B$6-0.07)-489.93)*5.5212+MAX(0,$B18-(Assumptions!$B$6-0.07))*0.65)) | E18: =IF($A18="","",IF(OR($C18="",$C18=0),0,MAX(0,MIN($C18,2999.4)-0)*0.0204+MAX(0,MIN($C18,4199.4)-2999.4)*0.0388+MAX(0,MIN($C18,Assumptions!$B$7-0.6)-4199.4)*0.2801+MAX(0,$C18-(Assumptions!$B$7-0.6))*0.042)) | F18: =IF($A18="","",D18+E18) | G18: =IF($A18="","",F18*(1-$B$8)) | H18: =IF($A18="","",DATE(YEAR($A18),MONTH($A18)+1,Assumptions!$B$5))
D19: =IF($A19="","",IF(OR($B19="",$B19=0),0,MAX(0,MIN($B19,349.93)-0)*0.3705+MAX(0,MIN($B19,489.93)-349.93)*0.9634+MAX(0,MIN($B19,Assumptions!$B$6-0.07)-489.93)*5.5212+MAX(0,$B19-(Assumptions!$B$6-0.07))*0.65)) | E19: =IF($A19="","",IF(OR($C19="",$C19=0),0,MAX(0,MIN($C19,2999.4)-0)*0.0204+MAX(0,MIN($C19,4199.4)-2999.4)*0.0388+MAX(0,MIN($C19,Assumptions!$B$7-0.6)-4199.4)*0.2801+MAX(0,$C19-(Assumptions!$B$7-0.6))*0.042)) | F19: =IF($A19="","",D19+E19) | G19: =IF($A19="","",F19*(1-$B$8)) | H19: =IF($A19="","",DATE(YEAR($A19),MONTH($A19)+1,Assumptions!$B$5))
D20: =IF($A20="","",IF(OR($B20="",$B20=0),0,MAX(0,MIN($B20,349.93)-0)*0.3705+MAX(0,MIN($B20,489.93)-349.93)*0.9634+MAX(0,MIN($B20,Assumptions!$B$6-0.07)-489.93)*5.5212+MAX(0,$B20-(Assumptions!$B$6-0.07))*0.65)) | E20: =IF($A20="","",IF(OR($C20="",$C20=0),0,MAX(0,MIN($C20,2999.4)-0)*0.0204+MAX(0,MIN($C20,4199.4)-2999.4)*0.0388+MAX(0,MIN($C20,Assumptions!$B$7-0.6)-4199.4)*0.2801+MAX(0,$C20-(Assumptions!$B$7-0.6))*0.042)) | F20: =IF($A20="","",D20+E20) | G20: =IF($A20="","",F20*(1-$B$8)) | H20: =IF($A20="","",DATE(YEAR($A20),MONTH($A20)+1,Assumptions!$B$5))
D21: =IF($A21="","",IF(OR($B21="",$B21=0),0,MAX(0,MIN($B21,349.93)-0)*0.3705+MAX(0,MIN($B21,489.93)-349.93)*0.9634+MAX(0,MIN($B21,Assumptions!$B$6-0.07)-489.93)*5.5212+MAX(0,$B21-(Assumptions!$B$6-0.07))*0.65)) | E21: =IF($A21="","",IF(OR($C21="",$C21=0),0,MAX(0,MIN($C21,2999.4)-0)*0.0204+MAX(0,MIN($C21,4199.4)-2999.4)*0.0388+MAX(0,MIN($C21,Assumptions!$B$7-0.6)-4199.4)*0.2801+MAX(0,$C21-(Assumptions!$B$7-0.6))*0.042)) | F21: =IF($A21="","",D21+E21) | G21: =IF($A21="","",F21*(1-$B$8)) | H21: =IF($A21="","",DATE(YEAR($A21),MONTH($A21)+1,Assumptions!$B$5))
D22: =IF($A22="","",IF(OR($B22="",$B22=0),0,MAX(0,MIN($B22,349.93)-0)*0.3705+MAX(0,MIN($B22,489.93)-349.93)*0.9634+MAX(0,MIN($B22,Assumptions!$B$6-0.07)-489.93)*5.5212+MAX(0,$B22-(Assumptions!$B$6-0.07))*0.65)) | E22: =IF($A22="","",IF(OR($C22="",$C22=0),0,MAX(0,MIN($C22,2999.4)-0)*0.0204+MAX(0,MIN($C22,4199.4)-2999.4)*0.0388+MAX(0,MIN($C22,Assumptions!$B$7-0.6)-4199.4)*0.2801+MAX(0,$C22-(Assumptions!$B$7-0.6))*0.042)) | F22: =IF($A22="","",D22+E22) | G22: =IF($A22="","",F22*(1-$B$8)) | H22: =IF($A22="","",DATE(YEAR($A22),MONTH($A22)+1,Assumptions!$B$5))
A24: COMMISSION SUMMARY
A25: Last 3 Months Avg Take-Home | B25: {=IFERROR(AVERAGE(_xlfn._xlws.FILTER(G11:G22,(A11:A22<>"")*(ISNUMBER(G11:G22)))),0)} -> 185.12734
A26: Commission Drought Flag | B26: {=IF(SUMPRODUCT((A11:A22<>"")*(IF(ISNUMBER(G11:G22),G11:G22<50,FALSE)))>=2,"⚠️ DROUGHT RISK","✅ OK")} -> ⚠️ DROUGHT RISK
A27: YTD Commission Take-Home | B27: {=SUMPRODUCT((A11:A22<>"")*(A11:A22>=DATE(YEAR(TODAY()),1,1))*(A11:A22<=DATE(YEAR(TODAY()),12,31))*IF(ISNUMBER(G11:G22),G11:G22,0))} -> 51.286462

Sheet Decision Sandbox
A1: Decision Sandbox
A2: Compare up to 4 options. Enter a name, price, and loan terms — leave fields blank if they don't apply.
A4: YOUR POSITION
A5: HYSA Balance | B5: ='Wealth Management 2026'!$B$4 -> 12500
A6: Daily Safe Spend | B6: =Dashboard!$B$21 -> 57.071429
A7: Monthly Fixed Bills | B7: =Dashboard!$B$57 -> 1523.95
A8: Monthly Variable Cap | B8: =Dashboard!$B$43 -> 600
A9: Base Net Income (per month) | B9: =Assumptions!$B$10 -> 3220
A11: PURCHASE COMPARISON | B11: Option 1 | C11: Option 2 | D11: Option 3 | E11: Option 4
A12: Option Name | B12: 23 Camry SE AWD | C12: 23 Crosstrek
A13: INPUTS
A14: Total Price | B14: 22124 | C14: 19721
A15: Down Payment | B15: 4000 | C15: 4000
A16: Interest Rate (%) | B16: 0.0474 | C16: 0.0474
A17: Loan Term (Months) | B17: 60 | C17: 60
A18: Monthly Add-ons (Ins/Tax/HOA) | B18: 165 | C18: 155
A19: One-Time Cost (if no loan)
A20: OUTPUTS
A21: Monthly Loan Payment | B21: =IF(B14="","",IF(OR(B16="",B16=0,B17="",B17=0),0,PMT(B16/12,B17,-(B14-IF(B15="",0,B15))))) -> 339.86756 | C21: =IF(C14="","",IF(OR(C16="",C16=0,C17="",C17=0),0,PMT(C16/12,C17,-(C14-IF(C15="",0,C15))))) -> 294.80566 | D21: =IF(D14="","",IF(OR(D16="",D16=0,D17="",D17=0),0,PMT(D16/12,D17,-(D14-IF(D15="",0,D15))))) | E21: =IF(E14="","",IF(OR(E16="",E16=0,E17="",E17=0),0,PMT(E16/12,E17,-(E14-IF(E15="",0,E15)))))
A22: Total Monthly Cost | B22: =IF(B14="",IF(B19="","",B19/12),IF(B21="","",B21+IF(B18="",0,B18))) -> 504.86756 | C22: =IF(C14="",IF(C19="","",C19/12),IF(C21="","",C21+IF(C18="",0,C18))) -> 449.80566 | D22: =IF(D14="",IF(D19="","",D19/12),IF(D21="","",D21+IF(D18="",0,D18))) | E22: =IF(E14="",IF(E19="","",E19/12),IF(E21="","",E21+IF(E18="",0,E18)))
A23: Daily Lifestyle Cost | B23: =IF(B22="","",B22/30.4) -> 16.607485 | C23: =IF(C22="","",C22/30.4) -> 14.796239 | D23: =IF(D22="","",D22/30.4) | E23: =IF(E22="","",E22/30.4)
A24: New Daily Safe Spend | B24: =IF(B23="","",B6-B23) -> 40.463943 | C24: =IF(C23="","",B6-C23) -> 42.27519 | D24: =IF(D23="","",B6-D23) | E24: =IF(E23="","",B6-E23)
A25: Annual Cost | B25: =IF(B22="","",IF(B14="",B19,B22*12)) -> 6058.4107 | C25: =IF(C22="","",IF(C14="",C19,C22*12)) -> 5397.668 | D25: =IF(D22="","",IF(D14="",D19,D22*12)) | E25: =IF(E22="","",IF(E14="",E19,E22*12))
A26: Total Interest Cost | B26: =IF(B14="","",IF(B17="",0,(B21*B17-(B14-IF(B15="",0,B15)))+IF(IF(B15="",0,B15)=0,0,FV(Assumptions!$B$12/12,120,0,-IF(B15="",0,B15))))) -> 10306.699 | C26: =IF(C14="","",IF(C17="",0,(C21*C17-(C14-IF(C15="",0,C15)))+IF(IF(C15="",0,C15)=0,0,FV(Assumptions!$B$12/12,120,0,-IF(C15="",0,C15))))) -> 10005.985 | D26: =IF(D14="","",IF(D17="",0,(D21*D17-(D14-IF(D15="",0,D15)))+IF(IF(D15="",0,D15)=0,0,FV(Assumptions!$B$12/12,120,0,-IF(D15="",0,D15))))) | E26: =IF(E14="","",IF(E17="",0,(E21*E17-(E14-IF(E15="",0,E15)))+IF(IF(E15="",0,E15)=0,0,FV(Assumptions!$B$12/12,120,0,-IF(E15="",0,E15)))))
A27: HYSA After Down Payment | B27: =IF(B14="",IF(B19="","",B5-B19),B5-IF(B15="",0,B15)) -> 8500 | C27: =IF(C14="",IF(C19="","",B5-C19),B5-IF(C15="",0,C15)) -> 8500 | D27: =IF(D14="",IF(D19="","",B5-D19),B5-IF(D15="",0,D15)) | E27: =IF(E14="",IF(E19="","",B5-E19),B5-IF(E15="",0,E15))
A28: Months of HYSA Runway | B28: =IF(B22="","",IF(B22=0,"∞",ROUND(B27/B22,1))) -> 16.8 | C28: =IF(C22="","",IF(C22=0,"∞",ROUND(C27/C22,1))) -> 18.9 | D28: =IF(D22="","",IF(D22=0,"∞",ROUND(D27/D22,1))) | E28: =IF(E22="","",IF(E22=0,"∞",ROUND(E27/E22,1)))
A29: Can You Afford It? | B29: =IF(B22="","",IF(B9-(B7+B22)>B8,"✅ Yes",IF(B9-(B7+B22)>0,"⚠️ Tight","❌ No"))) -> ✅ Yes | C29: =IF(C22="","",IF(B9-(B7+C22)>B8,"✅ Yes",IF(B9-(B7+C22)>0,"⚠️ Tight","❌ No"))) -> ✅ Yes | D29: =IF(D22="","",IF(B9-(B7+D22)>B8,"✅ Yes",IF(B9-(B7+D22)>0,"⚠️ Tight","❌ No"))) | E29: =IF(E22="","",IF(B9-(B7+E22)>B8,"✅ Yes",IF(B9-(B7+E22)>0,"⚠️ Tight","❌ No")))
A30: Income Coverage (%) | B30: =IF(B25="","",B25/(B9*12)) -> 0.15679117 | C30: =IF(C25="","",C25/(B9*12)) -> 0.1396912 | D30: =IF(D25="","",D25/(B9*12)) | E30: =IF(E25="","",E25/(B9*12))
A32: COMMISSION DROUGHT SURVIVAL
A33: Current Checking Balance | B33: =Dashboard!B6 -> 2152
A34: Current HYSA Balance | B34: ='Wealth Management 2026'!B20 -> 15000
A35: Total Liquid Cash | B35: =B33+B34 -> 17152
A36: Fixed Monthly Burn | B36: =Dashboard!B57 -> 1523.95
A37: Variable Monthly Spend Cap | B37: =Dashboard!B43 -> 600
A38: Total Monthly Burn (Base Only) | B38: =B36+B37 -> 2123.95
A39: Base Net Pay (No Commission) | B39: =Assumptions!B10 -> 3220
A40: Monthly Cash Deficit at $0 Commission | B40: =MAX(0,B38-B39) -> 0
A42: 🚨 ZERO-COMMISSION RUNWAY | B42: =IF(B40<=0,"INDEFINITE — base pay covers burn",IF(B35/B40>=12,TEXT(ROUND(B35/B40,1),"0.0")&" months (over 1 year)",TEXT(ROUND(B35/B40,1),"0.0")&" months")) -> INDEFINITE — base pay covers burn
A43: Monthly Surplus (base − burn) | B43: =IF(B40=0,B39-B38,0) -> 1096.05
A45: INCOME REPLACEMENT / NEGOTIATION FLOOR
...

Sheet Wealth Management 2026
A1: Wealth Management 2026
A3: Month | B3: HYSA | C3: Brokerage | D3: 401(k) | E3: Other Assets | F3: Total Assets | G3: Car Loan | H3: Student Loans | I3: Total Liab. | J3: Net Worth
A4: Jan | B4: 12500 | C4: 36073.35 | D4: 1550 | E4: 0 | F4: =IF(COUNTA(B4:E4)=0,"",SUM(B4:E4)) -> 50123.35 | G4: 0 | H4: 30000 | I4: =IF(COUNTA(G4:H4)=0,"",SUM(G4:H4)) -> 30000 | J4: =IF(AND(F4="",I4=""),"",N(F4)-N(I4)) -> 20123.35
A5: Feb | B5: 12500 | C5: 36073.35 | D5: 1750 | E5: 0 | F5: =IF(COUNTA(B5:E5)=0,"",SUM(B5:E5)) -> 50323.35 | G5: 0 | H5: 30000 | I5: =IF(COUNTA(G5:H5)=0,"",SUM(G5:H5)) -> 30000 | J5: =IF(AND(F5="",I5=""),"",N(F5)-N(I5)) -> 20323.35
A6: Mar | B6: 12600 | C6: 33962.45 | D6: 1850.45 | E6: 0 | F6: =IF(COUNTA(B6:E6)=0,"",SUM(B6:E6)) -> 48412.9 | G6: 0 | H6: 30000 | I6: =IF(COUNTA(G6:H6)=0,"",SUM(G6:H6)) -> 30000 | J6: =IF(AND(F6="",I6=""),"",N(F6)-N(I6)) -> 18412.9
A7: Apr | B7: 15000 | C7: 35500 | D7: 2200 | E7: 25000 | F7: =IF(COUNTA(B7:E7)=0,"",SUM(B7:E7)) -> 77700 | G7: 18000 | H7: 30000 | I7: =IF(COUNTA(G7:H7)=0,"",SUM(G7:H7)) -> 48000 | J7: =IF(AND(F7="",I7=""),"",N(F7)-N(I7)) -> 29700
A8: May | F8: =IF(COUNTA(B8:E8)=0,"",SUM(B8:E8)) | I8: =IF(COUNTA(G8:H8)=0,"",SUM(G8:H8)) | J8: =IF(AND(F8="",I8=""),"",N(F8)-N(I8))
A9: Jun | F9: =IF(COUNTA(B9:E9)=0,"",SUM(B9:E9)) | I9: =IF(COUNTA(G9:H9)=0,"",SUM(G9:H9)) | J9: =IF(AND(F9="",I9=""),"",N(F9)-N(I9))
A10: Jul | F10: =IF(COUNTA(B10:E10)=0,"",SUM(B10:E10)) | I10: =IF(COUNTA(G10:H10)=0,"",SUM(G10:H10)) | J10: =IF(AND(F10="",I10=""),"",N(F10)-N(I10))
A11: Aug | F11: =IF(COUNTA(B11:E11)=0,"",SUM(B11:E11)) | I11: =IF(COUNTA(G11:H11)=0,"",SUM(G11:H11)) | J11: =IF(AND(F11="",I11=""),"",N(F11)-N(I11))
A12: Sep | F12: =IF(COUNTA(B12:E12)=0,"",SUM(B12:E12)) | I12: =IF(COUNTA(G12:H12)=0,"",SUM(G12:H12)) | J12: =IF(AND(F12="",I12=""),"",N(F12)-N(I12))
A13: Oct | F13: =IF(COUNTA(B13:E13)=0,"",SUM(B13:E13)) | I13: =IF(COUNTA(G13:H13)=0,"",SUM(G13:H13)) | J13: =IF(AND(F13="",I13=""),"",N(F13)-N(I13))
A14: Nov | F14: =IF(COUNTA(B14:E14)=0,"",SUM(B14:E14)) | I14: =IF(COUNTA(G14:H14)=0,"",SUM(G14:H14)) | J14: =IF(AND(F14="",I14=""),"",N(F14)-N(I14))
A15: Dec | F15: =IF(COUNTA(B15:E15)=0,"",SUM(B15:E15)) | I15: =IF(COUNTA(G15:H15)=0,"",SUM(G15:H15)) | J15: =IF(AND(F15="",I15=""),"",N(F15)-N(I15))
A16: YTD Change | J16: {=IFERROR(LOOKUP(2,1/(J4:J15<>""),J4:J15)-J4,"")} -> 9576.65
A18: HYSA GAP TRACKER | G18: CREDIT SCORES
A19: HYSA Target | B19: =Assumptions!B11 -> 15000 | G19: Experian | H19: 756
A20: HYSA Current | B20: {=LOOKUP(2,1/(B4:B15<>""),B4:B15)} -> 15000 | G20: Equifax | H20: 754
A21: Gap to Target | B21: =MAX(0,B19-B20) -> 0 | G21: TransUnion | H21: 736
A22: Months to Close (Base Savings) | B22: =IFERROR(B21/(Dashboard!$B$62*Assumptions!$B$14),"") -> 0 | G22: Score Spread | H22: =MAX(H19:H21)-MIN(H19:H21) -> 20
G23: Last Checked | H23: 46030
A24: SAVINGS RATE | G24: ACTION PLAN
A25: Monthly Net Income | B25: =Dashboard!B54+Dashboard!B55 -> 3220 | G25: Utilization Target | H25: <10% all cards
A26: Est. Monthly Savings | B26: =Dashboard!B62 -> 9.5721053 | G26: Lowest Bureau | H26: =IF(H21=MIN(H19:H21),"TransUnion",IF(H20=MIN(H19:H21),"Equifax","Experian")) -> TransUnion
A27: Current Savings Rate | B27: =IFERROR(B26/(Assumptions!B35/12),0) -> 0.0021271345 | G27: Review Cadence | H27: Mar / Jun / Sep / Dec
A28: Target Savings Rate | B28: 0.2 | G28: Next Review | H28: 46174
A29: Gap to Target | B29: =IFERROR(B28-B27,"") -> 0.19787287
A31: NET WORTH PROJECTION
A32: Current Net Worth | B32: =J4 -> 20123.35
A33: Monthly Savings (floor) | B33: =B26 -> 9.5721053
A34: Annual Return on Investments | B34: =Assumptions!B12 -> 0.07
A35: Current Age | B35: 30
A37: Net Worth at Age 35 | B37: =FV(B34/12,(35-B35)*12,-B33,-B32) -> 29212.664
A38: Net Worth at Age 40 | B38: =FV(B34/12,(40-B35)*12,-B33,-B32) -> 42097.905
A39: Net Worth at Age 45 | B39: =FV(B34/12,(45-B35)*12,-B33,-B32) -> 60364.349
A41: BROKERAGE POLICY
A42: Purpose | B42: Long-term taxable investing (growth)
A43: Time Horizon | B43: 10+ years
A44: Touch Rules | B44: Do not withdraw for short-term needs
A46: Net Worth Trend Data
...

Sheet Assumptions
A1: CONTROL PANEL | B1: Value
A2: posting_cushion_days | B2: 1
A3: commission_tax_rate | B3: 0.435
A4: month_length_days | B4: 30.4
A5: commission_payout_day | B5: 22
A6: mrr_target | B6: 700
A7: nrr_target | B7: 6000
A8: alert_threshold | B8: 400
A9: variable_spend_cap | B9: 600
A10: base_net_income | B10: 3220
A11: hysa_target | B11: 15000
A12: retirement_return_assumption | B12: 0.07
A13: tax_annual_reserve | B13: 400
A14: savings_to_hysa_ratio | B14: 0.5
A15: include_forward_reserve_in_sts | B15: TRUE
A16: SESSION INTEGRITY CHECK (Section 6.0)
A17: Claude reads these at session start. Any FAIL = investigate before proceeding.
A19: # | B19: Check | C19: What Claude Verifies | D19: Status
A20: 1 | B20: Dashboard B15 formula | C20: Confirms =B11 (Bills-Only Reserve wired in) | D20: =IF(Dashboard!B15=Dashboard!B11,"✅ PASS","❌ FAIL") -> ✅ PASS
A21: 2 | B21: Dashboard B22 source | C21: Confirms Daily Rate uses formula not manual number | D21: =IF(_xlfn.ISFORMULA(Dashboard!B22),"✅ PASS","❌ FAIL") -> ✅ PASS
A22: 3 | B22: Dashboard B54 formula | C22: Confirms Base Net Income is formula-based (=Assumptions!B10) | D22: =IF(_xlfn.ISFORMULA(Dashboard!B54),"✅ PASS","❌ FAIL") -> ✅ PASS
A23: 4 | B23: Next Due Date logic | C23: Confirms Bills!D uses DATE(YEAR,MONTH,day) pattern | D23: =IF(_xlfn.ISFORMULA(Bills!D2),"✅ PASS","❌ FAIL") -> ✅ PASS
A24: 5 | B24: Car Loan row | C24: Confirms Bills!F6 Include=FALSE (car loan inactive) | D24: =IF(Bills!F6=FALSE,"✅ PASS","❌ FAIL") -> ✅ PASS
A25: 6 | B25: Claude Sub row | C25: Confirms Bills row 4: $21, Due 3rd, Include=TRUE | D25: =IF(AND(Bills!B4=21,Bills!C4=3,Bills!F4=TRUE),"✅ PASS","❌ FAIL") -> ✅ PASS
A26: 7 | B26: Forward Reserve | C26: Confirms Dashboard!B33 is formula-based or zero | D26: =IF(OR(_xlfn.ISFORMULA(Dashboard!B33),Dashboard!B33=0),"✅ PASS","❌ FAIL") -> ✅ PASS
A27: 8 | B27: Alert Threshold | C27: Confirms Assumptions!B8 is current (=400) | D27: =IF(B8=400,"✅ PASS","❌ FAIL") -> ✅ PASS
A28: 9 | B28: Monthly Savings formula | C28: Confirms Dashboard!B62 is a formula (Monthly Savings) | D28: =IF(_xlfn.ISFORMULA(Dashboard!B62),"✅ PASS","❌ FAIL") -> ✅ PASS
A29: 10 | B29: Wealth Mgmt NW Change | C29: Confirms WM!J16 uses formula (YTD Net Worth Change) | D29: =IF(_xlfn.ISFORMULA('Wealth Management 2026'!J16),"✅ PASS","❌ FAIL") -> ✅ PASS
A31: OVERALL STATUS | D31: =IF(COUNTIF(D20:D29,"❌ FAIL")>0,"❌ "&COUNTIF(D20:D29,"❌ FAIL")&" CHECK(S) FAILED","✅ ALL 10 CHECKS PASS") -> ✅ ALL 10 CHECKS PASS
A32: Last Verified | D32: =TEXT(TODAY(),"yyyy-mm-dd") -> 2026-04-23
A34: TAX PLANNING
A35: Gross Annual Income | B35: 54000
A36: Estimated Federal Tax Rate (Effective) | B36: 0.12
A37: Estimated State Tax Rate (Effective) | B37: 0.04
A38: Estimated Annual Tax Liability | B38: =B35*(B36+B37) -> 8640
A39: Pay Periods Per Year | B39: 24
A40: Tax Reserve Per Paycheck | B40: =B38/B39 -> 360
A41: Tax Reserve Per Month | B41: =B38/12 -> 720
A43: Note: If taxes are withheld from paycheck, this reserve covers any gap.
A44: Adjust effective rates based on actual refund/owed amounts.
...

Sheet Debt Strategy
A1: STUDENT LOAN DEBT STRATEGY
A2: All inputs in blue. All outputs are formulas.
A4: LOAN INPUTS
A5: Loan Servicer
A6: Total Loan Balance | B6: 30000
A7: Weighted Avg Interest Rate | B7: 0.055
A8: Loan Type | B8: Federal (Mixed Sub/Unsub)
A9: Current Repayment Status
A10: PSLF Eligible? | B10: No (Private employer)
A11: Current Monthly Payment | B11: 0
A12: Standard Plan Term (Years) | B12: 10
A13: Market Return Assumption | B13: =Assumptions!B12 -> 0.07
A14: Gross Annual Income | B14: 54000
A15: Monthly Net Income (2 checks) | B15: 3220
A16: Current Monthly Fixed Bills | B16: =Dashboard!B57 -> 1523.95
A18: STANDARD REPAYMENT ANALYSIS
A19: Monthly Payment (Standard 10yr) | B19: =PMT(B7/12,B12*12,-B6) -> 325.57883
A20: Total Paid (Standard 10yr) | B20: =B19*B12*12 -> 39069.46
A21: Total Interest (Standard 10yr) | B21: =B20-B6 -> 9069.4601
A23: Extended Plan Term (Years) | B23: 25
A24: Monthly Payment (Extended 25yr) | B24: =PMT(B7/12,B23*12,-B6) -> 184.22625
A25: Total Paid (Extended 25yr) | B25: =B24*B23*12 -> 55267.874
A26: Total Interest (Extended 25yr) | B26: =B25-B6 -> 25267.874
A28: Extra Interest Cost of Extended vs Standard | B28: =B26-B21 -> 16198.414
A30: ACCELERATED PAYOFF SCENARIOS
A32: Scenario | B32: 3-Year Payoff
A33: Monthly Payment Required | B33: =PMT(B7/12,3*12,-B6) -> 905.87705
A34: Total Interest Paid | B34: =(B33*36)-B6 -> 2611.5739
A35: Interest Saved vs Standard | B35: =B21-B34 -> 6457.8861
A37: Scenario | B37: 5-Year Payoff
A38: Monthly Payment Required | B38: =PMT(B7/12,5*12,-B6) -> 573.03487
A39: Total Interest Paid | B39: =(B38*60)-B6 -> 4382.0919
A40: Interest Saved vs Standard | B40: =B21-B39 -> 4687.3682
A42: Scenario | B42: 7-Year Payoff
A43: Monthly Payment Required | B43: =PMT(B7/12,7*12,-B6) -> 431.10128
A44: Total Interest Paid | B44: =(B43*84)-B6 -> 6212.5075
A45: Interest Saved vs Standard | B45: =B21-B44 -> 2856.9526
A47: IMPACT ON MONTHLY BURN & SAVINGS
A48: Current Monthly Savings Floor | B48: =B15-B16 -> 1696.05
A50: Savings After 3yr Payment | B50: =B48-B33 -> 790.17295
...

Sheet Retirement Planning
A1: RETIREMENT PLANNING
A2: 401(k) projections and contribution optimization. Blue = inputs.
A4: 401(k) INPUTS
A5: Gross Annual Income | B5: 54000
A6: Current Contribution Rate (% of Gross) | B6: 0.03
A7: Employer Match Rate | B7: 0.04
A8: Employer Match Cap (% of Gross) | B8: 0.04
A9: Current 401(k) Balance | B9: 1550
A10: Current Age | B10: 30
A11: Target Retirement Age | B11: 65
A12: Assumed Annual Return (Real) | B12: =Assumptions!B12 -> 0.07
A13: Assumed Annual Return (Nominal) | B13: 0.09
A16: Years to Retirement | B16: =B11-B10 -> 35
A18: CONTRIBUTION ANALYSIS
A19: Your Annual Contribution ($) | B19: =B5*B6 -> 1620
A20: Your Monthly Contribution ($) | B20: =B19/12 -> 135
A21: Employer Match Captured ($) | B21: =B5*MIN(B6,B8)*B7/B8 -> 1620
A22: Max Employer Match Available ($) | B22: =B5*B8 -> 2160
A24: ⚠️ MATCH GAP | B24: =IF(B6<B8,"LEAVING $"&TEXT(B22-B21,"#,##0")&" FREE MONEY ON THE TABLE — increase contribution to "&TEXT(B8,"0%")&" to capture full match","✅ Full match captured") -> LEAVING $540 FREE MONEY ON THE TABLE — increase contribution to 4% to capture full match
A26: 401(k) Contribution per Paycheck (bi-monthly) | B26: =B19/24 -> 67.5
A27: ↑ This should appear as a line item in Dashboard savings calc
A29: Total Annual Going In (You + Employer) | B29: =B19+B21 -> 3240
A31: PROJECTED BALANCE AT RETIREMENT
A32: Using 7% real return. Current balance + annual contributions compounded.
A34: At Current Rate (3%)
A35: Projected at Age 60 | B35: =FV(B12,60-B10,-B19-B21,-B9) -> 317851.94
A36: Projected at Age 65 | B36: =FV(B12,B16,-B19-B21,-B9) -> 464436.19
A38: If Contribution Increases to Match Cap (4%)
A39: Projected at Age 60 | B39: =FV(B12,60-B10,-(B5*B8)-(B5*B8),-B9) -> 419869.59
A40: Projected at Age 65 | B40: =FV(B12,B16,-(B5*B8)-(B5*B8),-B9) -> 613732.02
A42: If Contribution Increases to 10%
A43: Projected at Age 60 | B43: =FV(B12,60-B10,-(B5*0.1)-(B5*MIN(0.1,B8)*B7/B8),-B9) -> 725922.54
A44: Projected at Age 65 | B44: =FV(B12,B16,-(B5*0.1)-(B5*MIN(0.1,B8)*B7/B8),-B9) -> 1061619.5
A46: $1M TARGET CALCULATOR
A47: Target Balance at 65 | B47: 1000000
A49: Monthly Contribution Needed (You Only) | B49: =-PMT(B12/12,B16*12,-B9,B47) -> 545.32798
A50: Contribution Rate Needed (% of Gross) | B50: =B49*12/B5 -> 0.121184
A52: Note: This is your contribution only. Employer match is additional.
